Workbook

Sheet PROGRAMACAO
A1: Column1 | B1: Column2 | C1: Column3 | D1: Column4 | E1: Column5 | F1: Column6 | G1: Column7 | H1: Column8 | I1: Column9 | J1: Column10 | K1: Column11 | L1: Column12 | M1: Column13 | N1: Column14 | O1: Column15 | P1: Column16 | Q1: LATITUDE | R1: LONGITUDE | S1: CLIENTES PREVISTOS | T1: PROJETO KIT | U1: PROJETO MEDIDOR | V1: AR COELBA | W1: VISITA PRÉVIA | X1: OBSERVAÇÃO DA VISITA | Y1: ANÁLISE PRÉ FECH | Z1: SOLICITAÇÃO DE RESERVA
A2: ENCARREGADO | B2: SUPERVISOR | C2: PROJETO | D2: TITULO | E2: MUNICIPIO | F2: CRITÉRIO | G2: ANOTAÇÕES | H2: POSTE PREV | I2: INICIO | J2: TERMINO | K2: OBRA DA SEMANA | L2: MOTIVO DO ATRASO | M2: NECESSIDADE | N2: PROGRAMAÇÃO LV | O2: CAVA EXEC | Q2: =VLOOKUP(pub?gid_1064752002_single_true_output_csv[[#This Row],[Column3]],UTDNOVEMBRO!B:AQ,42,FALSE) -> #N/A | R2: =VLOOKUP(pub?gid_1064752002_single_true_output_csv[[#This Row],[Column3]],UTDNOVEMBRO!B:AU,43,FALSE) -> #N/A | S2: =VLOOKUP(pub?gid_1064752002_single_true_output_csv[[#This Row],[Column3]],UTDNOVEMBRO!B:AC,28,FALSE) -> #N/A | T2: =VLOOKUP(pub?gid_1064752002_single_true_output_csv[[#This Row],[Column3]],UTDNOVEMBRO!B:C,2,FALSE) -> #N/A | U2: =VLOOKUP(pub?gid_1064752002_single_true_output_csv[[#This Row],[Column3]],UTDNOVEMBRO!B:D,3,FALSE) -> #N/A | V2: =VLOOKUP(pub?gid_1064752002_single_true_output_csv[[#This Row],[Column3]],UTDNOVEMBRO!B:K,10,FALSE) -> #N/A | W2: =VLOOKUP(pub?gid_1064752002_single_true_output_csv[[#This Row],[Column3]],UTDNOVEMBRO!B:N,13,FALSE) -> #N/A | X2: =VLOOKUP(pub?gid_1064752002_single_true_output_csv[[#This Row],[Column3]],UTDNOVEMBRO!B:O,14,FALSE) -> #N/A | Y2: =VLOOKUP(pub?gid_1064752002_single_true_output_csv[[#This Row],[Column3]],UTDNOVEMBRO!B:P,15,FALSE) -> #N/A | Z2: =VLOOKUP(pub?gid_1064752002_single_true_output_csv[[#This Row],[Column3]],UTDNOVEMBRO!B:Q,15,FALSE) -> #N/A
A3: ALEX SANDRO | B3: DJALMA | C3: B-1214123 | D3: IP-SEIN-RUA-JOAO DOURADO-NOVO CANAL | E3: JOÃO DOURADO | F3: GOVERNO | G3: OBRA DE INFLAESTRUTURA IP | H3: 54 | I3: 03/11/2025 | J3: 30/11/2025 | K3: ATUANDO | M3: LV | O3: 64 | P3: 47 | Q3: =VLOOKUP(pub?gid_1064752002_single_true_output_csv[[#This Row],[Column3]],UTDNOVEMBRO!B:AQ,42,FALSE) -> -11.346185 | R3: =VLOOKUP(pub?gid_1064752002_single_true_output_csv[[#This Row],[Column3]],UTDNOVEMBRO!B:AU,43,FALSE) -> -41.639873 | S3: =VLOOKUP(pub?gid_1064752002_single_true_output_csv[[#This Row],[Column3]],UTDNOVEMBRO!B:AC,28,FALSE) -> 0 | T3: =VLOOKUP(pub?gid_1064752002_single_true_output_csv[[#This Row],[Column3]],UTDNOVEMBRO!B:C,2,FALSE) | U3: =VLOOKUP(pub?gid_1064752002_single_true_output_csv[[#This Row],[Column3]],UTDNOVEMBRO!B:D,3,FALSE) | V3: =VLOOKUP(pub?gid_1064752002_single_true_output_csv[[#This Row],[Column3]],UTDNOVEMBRO!B:K,10,FALSE) -> PEDRO ANDERSON NERI DE SOUZA - U465037 | W3: =VLOOKUP(pub?gid_1064752002_single_true_output_csv[[#This Row],[Column3]],UTDNOVEMBRO!B:N,13,FALSE) -> 28/10/25 | X3: =VLOOKUP(pub?gid_1064752002_single_true_output_csv[[#This Row],[Column3]],UTDNOVEMBRO!B:O,14,FALSE) -> ALTERAR DERIVAÇÃO. EXTENDER A REDE BT PELOS POSTES DA SEQUENCIA B678842, B678843 | Y3: =VLOOKUP(pub?gid_1064752002_single_true_output_csv[[#This Row],[Column3]],UTDNOVEMBRO!B:P,15,FALSE) -> 29/10/25 | Z3: =VLOOKUP(pub?gid_1064752002_single_true_output_csv[[#This Row],[Column3]],UTDNOVEMBRO!B:Q,15,FALSE) -> 29/10/25
A4: IRISMAR | B4: HIAGO | C4: B-1228719 | D4: AC-CIND-POV-MORRINHO DE ARTURZINHO-RURAL | E4: CANARANA | F4: QLP | G4: ENERGIZADA | H4: 1 | I4: 03/11/2025 | J4: 03/11/2025 | K4: ENERGIZADA | M4: LV | N4: REALIZADO | O4: 1 | P4: 1 | Q4: =VLOOKUP(pub?gid_1064752002_single_true_output_csv[[#This Row],[Column3]],UTDNOVEMBRO!B:AQ,42,FALSE) -> -11,788833 | R4: =VLOOKUP(pub?gid_1064752002_single_true_output_csv[[#This Row],[Column3]],UTDNOVEMBRO!B:AU,43,FALSE) -> -41,768644 | S4: =VLOOKUP(pub?gid_1064752002_single_true_output_csv[[#This Row],[Column3]],UTDNOVEMBRO!B:AC,28,FALSE) -> 0 | T4: =VLOOKUP(pub?gid_1064752002_single_true_output_csv[[#This Row],[Column3]],UTDNOVEMBRO!B:C,2,FALSE) -> N/A | U4: =VLOOKUP(pub?gid_1064752002_single_true_output_csv[[#This Row],[Column3]],UTDNOVEMBRO!B:D,3,FALSE) -> N/A | V4: =VLOOKUP(pub?gid_1064752002_single_true_output_csv[[#This Row],[Column3]],UTDNOVEMBRO!B:K,10,FALSE) -> MANOEL MESSIAS ALENCAR - U359765 | W4: =VLOOKUP(pub?gid_1064752002_single_true_output_csv[[#This Row],[Column3]],UTDNOVEMBRO!B:N,13,FALSE) -> 07/10/25 | X4: =VLOOKUP(pub?gid_1064752002_single_true_output_csv[[#This Row],[Column3]],UTDNOVEMBRO!B:O,14,FALSE) -> NTERCALAR POSTE 11/600 COM TRANSFORMADOR ENTRE OS POSTES | Y4: =VLOOKUP(pub?gid_1064752002_single_true_output_csv[[#This Row],[Column3]],UTDNOVEMBRO!B:P,15,FALSE) -> 07/10/25 | Z4: =VLOOKUP(pub?gid_1064752002_single_true_output_csv[[#This Row],[Column3]],UTDNOVEMBRO!B:Q,15,FALSE) -> 07/10/25
A5: JAILSON | B5: HIAGO | C5: B-1206961 | D5: ER-CIND-POV-CAMPO FORMOSO-RURAL | E5: BARRO ALTO | F5: QLP | G5: ENERGIZADA | H5: 10 | I5: 03/11/2025 | J5: 11/11/2025 | K5: ENERGIZADA | M5: DP | N5: REALIZADO | O5: 10 | P5: 10 | Q5: =VLOOKUP(pub?gid_1064752002_single_true_output_csv[[#This Row],[Column3]],UTDNOVEMBRO!B:AQ,42,FALSE) -> -11,874596 | R5: =VLOOKUP(pub?gid_1064752002_single_true_output_csv[[#This Row],[Column3]],UTDNOVEMBRO!B:AU,43,FALSE) -> -41,850519 | S5: =VLOOKUP(pub?gid_1064752002_single_true_output_csv[[#This Row],[Column3]],UTDNOVEMBRO!B:AC,28,FALSE) -> 1 | T5: =VLOOKUP(pub?gid_1064752002_single_true_output_csv[[#This Row],[Column3]],UTDNOVEMBRO!B:C,2,FALSE) -> N/A | U5: =VLOOKUP(pub?gid_1064752002_single_true_output_csv[[#This Row],[Column3]],UTDNOVEMBRO!B:D,3,FALSE) -> N/A | V5: =VLOOKUP(pub?gid_1064752002_single_true_output_csv[[#This Row],[Column3]],UTDNOVEMBRO!B:K,10,FALSE) -> ALINE LIMA SILVA - U468383 | W5: =VLOOKUP(pub?gid_1064752002_single_true_output_csv[[#This Row],[Column3]],UTDNOVEMBRO!B:N,13,FALSE) -> 13/10/25 | X5: =VLOOKUP(pub?gid_1064752002_single_true_output_csv[[#This Row],[Column3]],UTDNOVEMBRO!B:O,14,FALSE) -> OBRA APITA OARA CONSTRUÇÃO CONFORME PROJETO | Y5: =VLOOKUP(pub?gid_1064752002_single_true_output_csv[[#This Row],[Column3]],UTDNOVEMBRO!B:P,15,FALSE) -> 14/10/25 | Z5: =VLOOKUP(pub?gid_1064752002_single_true_output_csv[[#This Row],[Column3]],UTDNOVEMBRO!B:Q,15,FALSE) -> 14/10/25
A6: IRISMAR | B6: HIAGO | C6: B-1232945 | D6: ER-CIND-POV-ALEIXO-RURAL | E6: IBIPEBA | F6: JUDICIAL | G6: ENERGIZADA | H6: 8 | I6: 05/11/2025 | J6: 06/11/2025 | K6: ENERGIZADA | O6: 5 | P6: 8 | Q6: =VLOOKUP(pub?gid_1064752002_single_true_output_csv[[#This Row],[Column3]],UTDNOVEMBRO!B:AQ,42,FALSE) -> -11.662674 | R6: =VLOOKUP(pub?gid_1064752002_single_true_output_csv[[#This Row],[Column3]],UTDNOVEMBRO!B:AU,43,FALSE) -> -42.010983 | S6: =VLOOKUP(pub?gid_1064752002_single_true_output_csv[[#This Row],[Column3]],UTDNOVEMBRO!B:AC,28,FALSE) -> 5 | T6: =VLOOKUP(pub?gid_1064752002_single_true_output_csv[[#This Row],[Column3]],UTDNOVEMBRO!B:C,2,FALSE) -> B-1235747 | U6: =VLOOKUP(pub?gid_1064752002_single_true_output_csv[[#This Row],[Column3]],UTDNOVEMBRO!B:D,3,FALSE) -> B-1235754 | V6: =VLOOKUP(pub?gid_1064752002_single_true_output_csv[[#This Row],[Column3]],UTDNOVEMBRO!B:K,10,FALSE) -> ALINE LIMA SILVA - U468383 | W6: =VLOOKUP(pub?gid_1064752002_single_true_output_csv[[#This Row],[Column3]],UTDNOVEMBRO!B:N,13,FALSE) -> 28/10/25 | X6: =VLOOKUP(pub?gid_1064752002_single_true_output_csv[[#This Row],[Column3]],UTDNOVEMBRO!B:O,14,FALSE) -> OBRA APITA PARA CONSTRUÇÃO DE ACORDO PROJETO | Y6: =VLOOKUP(pub?gid_1064752002_single_true_output_csv[[#This Row],[Column3]],UTDNOVEMBRO!B:P,15,FALSE) -> 29/10/25 | Z6: =VLOOKUP(pub?gid_1064752002_single_true_output_csv[[#This Row],[Column3]],UTDNOVEMBRO!B:Q,15,FALSE) -> 29/10/25
A7: ALAN | B7: DJALMA | C7: B-1099615 | D7: ER-CIND-POV-PREVINIDO-RURAL | E7: AMÉRICA DOURADA | F7: REPUTACIONAL | G7: ENERGIZADA | H7: 4 | I7: 03/11/2025 | J7: 04/11/2025 | K7: ENERGIZADA | M7: LV | N7: REALIZADO | O7: 0 | P7: 4 | Q7: =VLOOKUP(pub?gid_1064752002_single_true_output_csv[[#This Row],[Column3]],UTDNOVEMBRO!B:AQ,42,FALSE) -> -11,440433 | R7: =VLOOKUP(pub?gid_1064752002_single_true_output_csv[[#This Row],[Column3]],UTDNOVEMBRO!B:AU,43,FALSE) -> -41,601552 | S7: =VLOOKUP(pub?gid_1064752002_single_true_output_csv[[#This Row],[Column3]],UTDNOVEMBRO!B:AC,28,FALSE) -> 3 | T7: =VLOOKUP(pub?gid_1064752002_single_true_output_csv[[#This Row],[Column3]],UTDNOVEMBRO!B:C,2,FALSE) -> B-1231514 | U7: =VLOOKUP(pub?gid_1064752002_single_true_output_csv[[#This Row],[Column3]],UTDNOVEMBRO!B:D,3,FALSE) -> B-1231533 | V7: =VLOOKUP(pub?gid_1064752002_single_true_output_csv[[#This Row],[Column3]],UTDNOVEMBRO!B:K,10,FALSE) -> JOSE ANTONIO SIMAS NETO - U349485 | W7: =VLOOKUP(pub?gid_1064752002_single_true_output_csv[[#This Row],[Column3]],UTDNOVEMBRO!B:N,13,FALSE) -> 09/10/25 | X7: =VLOOKUP(pub?gid_1064752002_single_true_output_csv[[#This Row],[Column3]],UTDNOVEMBRO!B:O,14,FALSE) -> EXISTE UMA OBRA JA EXECUTADA, POREM, NAO TEM TRAFO PARA ATENDER OS CLIENTES. VERIFICAR POSSIBILIDADE DE ATENDER CONFORME OS PONTOS. | Y7: =VLOOKUP(pub?gid_1064752002_single_true_output_csv[[#This Row],[Column3]],UTDNOVEMBRO!B:P,15,FALSE) -> 13/10/25 | Z7: =VLOOKUP(pub?gid_1064752002_single_true_output_csv[[#This Row],[Column3]],UTDNOVEMBRO!B:Q,15,FALSE) -> 13/10/25
A8: MARCOS PAULO | B8: HIAGO | C8: B-1156355 | D8: MP CIND POV DE CEDRO RURAL | E8: GENTIO DO OURO | F8: QLP | G8: ENERGIZADA | H8: 15 | I8: 03/11/2025 | J8: 11/11/2025 | K8: ENERGIZADA | M8: DP/LV | N8: 12/11/2025 | O8: 17 | P8: 12 | Q8: =VLOOKUP(pub?gid_1064752002_single_true_output_csv[[#This Row],[Column3]],UTDNOVEMBRO!B:AQ,42,FALSE) -> -11,630717 | R8: =VLOOKUP(pub?gid_1064752002_single_true_output_csv[[#This Row],[Column3]],UTDNOVEMBRO!B:AU,43,FALSE) -> -42,612684 | S8: =VLOOKUP(pub?gid_1064752002_single_true_output_csv[[#This Row],[Column3]],UTDNOVEMBRO!B:AC,28,FALSE) -> 1 | T8: =VLOOKUP(pub?gid_1064752002_single_true_output_csv[[#This Row],[Column3]],UTDNOVEMBRO!B:C,2,FALSE) -> B-1235762 | U8: =VLOOKUP(pub?gid_1064752002_single_true_output_csv[[#This Row],[Column3]],UTDNOVEMBRO!B:D,3,FALSE) -> B-1156352 | V8: =VLOOKUP(pub?gid_1064752002_single_true_output_csv[[#This Row],[Column3]],UTDNOVEMBRO!B:K,10,FALSE) -> JOSE EDUARDO GOMES DOS SANTOS LIMA - U468835 | W8: =VLOOKUP(pub?gid_1064752002_single_true_output_csv[[#This Row],[Column3]],UTDNOVEMBRO!B:N,13,FALSE) -> 20/10/25 | X8: =VLOOKUP(pub?gid_1064752002_single_true_output_csv[[#This Row],[Column3]],UTDNOVEMBRO!B:O,14,FALSE) -> OBRA APITAR PARA CONSTRUÇÃO CONFORME PROJETO. | Y8: =VLOOKUP(pub?gid_1064752002_single_true_output_csv[[#This Row],[Column3]],UTDNOVEMBRO!B:P,15,FALSE) -> 21/10/25 | Z8: =VLOOKUP(pub?gid_1064752002_single_true_output_csv[[#This Row],[Column3]],UTDNOVEMBRO!B:Q,15,FALSE) -> 21/10/25
A9: EDILSON | B9: DJALMA | C9: B-1227493 | D9: ER-CIND-FAZ-S O JORGE-SOARES | E9: AMÉRICA DOURADA | F9: QLP | G9: DP 18/11 - ADF INTERCALAR POSTE 12/600 N1 TT COM TR 30KvA EM REDE 3X04 13,8Kv | H9: 8 | I9: 13/11/2025 | J9: 18/11/2025 | K9: ATUANDO | M9: DP | O9: 0 | P9: 3 | Q9: =VLOOKUP(pub?gid_1064752002_single_true_output_csv[[#This Row],[Column3]],UTDNOVEMBRO!B:AQ,42,FALSE) -> -11,324178 | R9: =VLOOKUP(pub?gid_1064752002_single_true_output_csv[[#This Row],[Column3]],UTDNOVEMBRO!B:AU,43,FALSE) -> -41,463986 | S9: =VLOOKUP(pub?gid_1064752002_single_true_output_csv[[#This Row],[Column3]],UTDNOVEMBRO!B:AC,28,FALSE) -> 1 | T9: =VLOOKUP(pub?gid_1064752002_single_true_output_csv[[#This Row],[Column3]],UTDNOVEMBRO!B:C,2,FALSE) | U9: =VLOOKUP(pub?gid_1064752002_single_true_output_csv[[#This Row],[Column3]],UTDNOVEMBRO!B:D,3,FALSE) | V9: =VLOOKUP(pub?gid_1064752002_single_true_output_csv[[#This Row],[Column3]],UTDNOVEMBRO!B:K,10,FALSE) -> JOSE ANTONIO SIMAS NETO - U349485 | W9: =VLOOKUP(pub?gid_1064752002_single_true_output_csv[[#This Row],[Column3]],UTDNOVEMBRO!B:N,13,FALSE) -> 09/10/25 | X9: =VLOOKUP(pub?gid_1064752002_single_true_output_csv[[#This Row],[Column3]],UTDNOVEMBRO!B:O,14,FALSE) -> EXECUTAR ADF CONFORME PROJETO. | Y9: =VLOOKUP(pub?gid_1064752002_single_true_output_csv[[#This Row],[Column3]],UTDNOVEMBRO!B:P,15,FALSE) -> 09/10/25 | Z9: =VLOOKUP(pub?gid_1064752002_single_true_output_csv[[#This Row],[Column3]],UTDNOVEMBRO!B:Q,15,FALSE) -> 09/10/25
A10: IRISMAR | B10: HIAGO | C10: B-1152082 | D10: AC - CIND POV ACHADO - RURAL | E10: BARRO ALTO | F10: QLP | G10: DP 13/11 - ADF MT | H10: 0 | I10: 12/11/2025 | J10: 13/11/2025 | K10: ATUANDO | M10: LV | O10: 0 | P10: 0 | Q10: =VLOOKUP(pub?gid_1064752002_single_true_output_csv[[#This Row],[Column3]],UTDNOVEMBRO!B:AQ,42,FALSE) -> -11,808347 | R10: =VLOOKUP(pub?gid_1064752002_single_true_output_csv[[#This Row],[Column3]],UTDNOVEMBRO!B:AU,43,FALSE) -> -41,852638 | S10: =VLOOKUP(pub?gid_1064752002_single_true_output_csv[[#This Row],[Column3]],UTDNOVEMBRO!B:AC,28,FALSE) -> 1 | T10: =VLOOKUP(pub?gid_1064752002_single_true_output_csv[[#This Row],[Column3]],UTDNOVEMBRO!B:C,2,FALSE) -> N/A | U10: =VLOOKUP(pub?gid_1064752002_single_true_output_csv[[#This Row],[Column3]],UTDNOVEMBRO!B:D,3,FALSE) -> N/A | V10: =VLOOKUP(pub?gid_1064752002_single_true_output_csv[[#This Row],[Column3]],UTDNOVEMBRO!B:K,10,FALSE) -> ALINE LIMA SILVA - U468383 | W10: =VLOOKUP(pub?gid_1064752002_single_true_output_csv[[#This Row],[Column3]],UTDNOVEMBRO!B:N,13,FALSE) -> 13/10/25 | X10: =VLOOKUP(pub?gid_1064752002_single_true_output_csv[[#This Row],[Column3]],UTDNOVEMBRO!B:O,14,FALSE) -> OBRA APITA PARA CONSTRUÇÃO | Y10: =VLOOKUP(pub?gid_1064752002_single_true_output_csv[[#This Row],[Column3]],UTDNOVEMBRO!B:P,15,FALSE) -> 14/10/25 | Z10: =VLOOKUP(pub?gid_1064752002_single_true_output_csv[[#This Row],[Column3]],UTDNOVEMBRO!B:Q,15,FALSE) -> 14/10/25
A11: VANILSON | B11: DJALMA | C11: B-1218109 | D11: ER-CIND-POV-FLORESTA IRINEUS-RURAL | E11: JOÃO DOURADO | F11: QLP | G11: N3 PRA N4 EM POSTE EXISTENTE EM REDE 2X04 13,8Kv | H11: 19 | I11: 03/11/2025 | J11: 12/11/2025 | K11: ATRASADA | M11: LV | O11: 17 | P11: 21 | Q11: =VLOOKUP(pub?gid_1064752002_single_true_output_csv[[#This Row],[Column3]],UTDNOVEMBRO!B:AQ,42,FALSE) -> -11,243142 | R11: =VLOOKUP(pub?gid_1064752002_single_true_output_csv[[#This Row],[Column3]],UTDNOVEMBRO!B:AU,43,FALSE) -> -41,548018 | S11: =VLOOKUP(pub?gid_1064752002_single_true_output_csv[[#This Row],[Column3]],UTDNOVEMBRO!B:AC,28,FALSE) -> 2 | T11: =VLOOKUP(pub?gid_1064752002_single_true_output_csv[[#This Row],[Column3]],UTDNOVEMBRO!B:C,2,FALSE) | U11: =VLOOKUP(pub?gid_1064752002_single_true_output_csv[[#This Row],[Column3]],UTDNOVEMBRO!B:D,3,FALSE) | V11: =VLOOKUP(pub?gid_1064752002_single_true_output_csv[[#This Row],[Column3]],UTDNOVEMBRO!B:K,10,FALSE) -> PEDRO ANDERSON NERI DE SOUZA - U465037 | W11: =VLOOKUP(pub?gid_1064752002_single_true_output_csv[[#This Row],[Column3]],UTDNOVEMBRO!B:N,13,FALSE) -> 22/10/25 | X11: =VLOOKUP(pub?gid_1064752002_single_true_output_csv[[#This Row],[Column3]],UTDNOVEMBRO!B:O,14,FALSE) -> OBRA APITAR PARA CONSTRUÇÃO. ADF JÁ FOI CONATRUIDA. DE N3-3 PARA N4-3 LV | Y11: =VLOOKUP(pub?gid_1064752002_single_true_output_csv[[#This Row],[Column3]],UTDNOVEMBRO!B:P,15,FALSE) -> 23/10/25 | Z11: =VLOOKUP(pub?gid_1064752002_single_true_output_csv[[#This Row],[Column3]],UTDNOVEMBRO!B:Q,15,FALSE) -> 23/10/25
A12: JAILSON | B12: HIAGO | C12: B-1207659 | D12: UB-CIND-POV-PENDAO VERMELHO-CENTRO | E12: BARRO ALTO | F12: QLP | G12: DP 19/11 E 21/11 - ADF | H12: 8 | I12: 14/11/2025 | J12: 19/11/2025 | K12: PROGRAMADA | M12: DP/LV | O12: 8 | P12: 2 | Q12: =VLOOKUP(pub?gid_1064752002_single_true_output_csv[[#This Row],[Column3]],UTDNOVEMBRO!B:AQ,42,FALSE) -> -11,870811 | R12: =VLOOKUP(pub?gid_1064752002_single_true_output_csv[[#This Row],[Column3]],UTDNOVEMBRO!B:AU,43,FALSE) -> -41,830110 | S12: =VLOOKUP(pub?gid_1064752002_single_true_output_csv[[#This Row],[Column3]],UTDNOVEMBRO!B:AC,28,FALSE) -> 1 | T12: =VLOOKUP(pub?gid_1064752002_single_true_output_csv[[#This Row],[Column3]],UTDNOVEMBRO!B:C,2,FALSE) -> N/A | U12: =VLOOKUP(pub?gid_1064752002_single_true_output_csv[[#This Row],[Column3]],UTDNOVEMBRO!B:D,3,FALSE) -> N/A | V12: =VLOOKUP(pub?gid_1064752002_single_true_output_csv[[#This Row],[Column3]],UTDNOVEMBRO!B:K,10,FALSE) -> ALINE LIMA SILVA - U468383 | W12: =VLOOKUP(pub?gid_1064752002_single_true_output_csv[[#This Row],[Column3]],UTDNOVEMBRO!B:N,13,FALSE) -> 09/10/25 | X12: =VLOOKUP(pub?gid_1064752002_single_true_output_csv[[#This Row],[Column3]],UTDNOVEMBRO!B:O,14,FALSE) -> OBRAS APITA PARA CONSTRUÇÃO, B-1207659, B-1225231 UMA DEPENDE DA OUTRA NO QUE SE DIZ RESPEITO A ADF. SÃO A MESMA DERIVAÇÃO | Y12: =VLOOKUP(pub?gid_1064752002_single_true_output_csv[[#This Row],[Column3]],UTDNOVEMBRO!B:P,15,FALSE) -> 16/10/25 | Z12: =VLOOKUP(pub?gid_1064752002_single_true_output_csv[[#This Row],[Column3]],UTDNOVEMBRO!B:Q,15,FALSE) -> 16/10/25
A13: JAILSON | B13: HIAGO | C13: B-1225231 | D13: ER-CIND-POV-PENDAO VERMELHO-PENDAO VERME | E13: BARRO ALTO | F13: QLP | G13: N3-3 PARA N4-3 EM POSTE EXISTENTE EM REDE 3X04 13,8Kv | H13: 15 | I13: 20/11/2025 | J13: 25/11/2025 | K13: PROGRAMADA | M13: LV | O13: 14 | P13: 0 | Q13: =VLOOKUP(pub?gid_1064752002_single_true_output_csv[[#This Row],[Column3]],UTDNOVEMBRO!B:AQ,42,FALSE) -> -11,870811 | R13: =VLOOKUP(pub?gid_1064752002_single_true_output_csv[[#This Row],[Column3]],UTDNOVEMBRO!B:AU,43,FALSE) -> -41,830110 | S13: =VLOOKUP(pub?gid_1064752002_single_true_output_csv[[#This Row],[Column3]],UTDNOVEMBRO!B:AC,28,FALSE) -> 1 | T13: =VLOOKUP(pub?gid_1064752002_single_true_output_csv[[#This Row],[Column3]],UTDNOVEMBRO!B:C,2,FALSE) | U13: =VLOOKUP(pub?gid_1064752002_single_true_output_csv[[#This Row],[Column3]],UTDNOVEMBRO!B:D,3,FALSE) | V13: =VLOOKUP(pub?gid_1064752002_single_true_output_csv[[#This Row],[Column3]],UTDNOVEMBRO!B:K,10,FALSE) -> ALINE LIMA SILVA - U468383 | W13: =VLOOKUP(pub?gid_1064752002_single_true_output_csv[[#This Row],[Column3]],UTDNOVEMBRO!B:N,13,FALSE) -> 16/10/25 | X13: =VLOOKUP(pub?gid_1064752002_single_true_output_csv[[#This Row],[Column3]],UTDNOVEMBRO!B:O,14,FALSE) -> OBRAS APITA PARA CONSTRUÇÃO, B-1207659, B-1225231 UMA DEPENDE DA OUTRA NO QUE SE DIZ RESPEITO A ADF. SÃO A MESMA DERIVAÇÃO | Y13: =VLOOKUP(pub?gid_1064752002_single_true_output_csv[[#This Row],[Column3]],UTDNOVEMBRO!B:P,15,FALSE) -> 16/10/25 | Z13: =VLOOKUP(pub?gid_1064752002_single_true_output_csv[[#This Row],[Column3]],UTDNOVEMBRO!B:Q,15,FALSE) -> 16/10/25
A14: JAILSON | B14: HIAGO | C14: B-1210478 | D14: ER-CIND-POV PIMENTA 147-PIMENTA | E14: CAFARNAUM | F14: QLP | G14: N3-3 PARA N4-3 EM POSTE EXISTENTE EM REDE 2X04 13,8Kv | H14: 15 | I14: 26/11/2025 | J14: 30/11/2025 | K14: PROGRAMADA | M14: LV | O14: 1 | P14: 0 | Q14: =VLOOKUP(pub?gid_1064752002_single_true_output_csv[[#This Row],[Column3]],UTDNOVEMBRO!B:AQ,42,FALSE) -> -11,854066 | R14: =VLOOKUP(pub?gid_1064752002_single_true_output_csv[[#This Row],[Column3]],UTDNOVEMBRO!B:AU,43,FALSE) -> -41,613738 | S14: =VLOOKUP(pub?gid_1064752002_single_true_output_csv[[#This Row],[Column3]],UTDNOVEMBRO!B:AC,28,FALSE) -> 1 | T14: =VLOOKUP(pub?gid_1064752002_single_true_output_csv[[#This Row],[Column3]],UTDNOVEMBRO!B:C,2,FALSE) -> X-1235682 | U14: =VLOOKUP(pub?gid_1064752002_single_true_output_csv[[#This Row],[Column3]],UTDNOVEMBRO!B:D,3,FALSE) -> X-1235709 | V14: =VLOOKUP(pub?gid_1064752002_single_true_output_csv[[#This Row],[Column3]],UTDNOVEMBRO!B:K,10,FALSE) -> MANOEL MESSIAS ALENCAR - U359765 | W14: =VLOOKUP(pub?gid_1064752002_single_true_output_csv[[#This Row],[Column3]],UTDNOVEMBRO!B:N,13,FALSE) -> 15/10/25 | X14: =VLOOKUP(pub?gid_1064752002_single_true_output_csv[[#This Row],[Column3]],UTDNOVEMBRO!B:O,14,FALSE) -> A OBRA DERIVA DA ULTIMA N3-3 DA ADF DE PIMENTA B-1156677, ENCABEÇAR REDE MT CONFORME PROJETO. N3-3 PARA N4-3 | Y14: =VLOOKUP(pub?gid_1064752002_single_true_output_csv[[#This Row],[Column3]],UTDNOVEMBRO!B:P,15,FALSE) -> 16/10/25 | Z14: =VLOOKUP(pub?gid_1064752002_single_true_output_csv[[#This Row],[Column3]],UTDNOVEMBRO!B:Q,15,FALSE) -> 16/10/25
A15: EDILSON | B15: DJALMA | C15: B-1207274 | D15: RR-CIND-FAZ-BOA VISTA-RURAL | E15: MORRO DO CHAPÉU | F15: QLP | G15: ENERGIZADA | H15: 12 | I15: 03/11/2025 | J15: 10/11/2025 | K15: ENERGIZADA | M15: DP/LV | N15: REALIZADO | O15: 12 | P15: 10 | Q15: =VLOOKUP(pub?gid_1064752002_single_true_output_csv[[#This Row],[Column3]],UTDNOVEMBRO!B:AQ,42,FALSE) -> -11,633036 | R15: =VLOOKUP(pub?gid_1064752002_single_true_output_csv[[#This Row],[Column3]],UTDNOVEMBRO!B:AU,43,FALSE) -> -41,149286 | S15: =VLOOKUP(pub?gid_1064752002_single_true_output_csv[[#This Row],[Column3]],UTDNOVEMBRO!B:AC,28,FALSE) -> 1 | T15: =VLOOKUP(pub?gid_1064752002_single_true_output_csv[[#This Row],[Column3]],UTDNOVEMBRO!B:C,2,FALSE) -> N/A | U15: =VLOOKUP(pub?gid_1064752002_single_true_output_csv[[#This Row],[Column3]],UTDNOVEMBRO!B:D,3,FALSE) -> N/A | V15: =VLOOKUP(pub?gid_1064752002_single_true_output_csv[[#This Row],[Column3]],UTDNOVEMBRO!B:K,10,FALSE) -> JOSE ANTONIO SIMAS NETO - U349485 | W15: =VLOOKUP(pub?gid_1064752002_single_true_output_csv[[#This Row],[Column3]],UTDNOVEMBRO!B:N,13,FALSE) -> 13/10/25 | X15: =VLOOKUP(pub?gid_1064752002_single_true_output_csv[[#This Row],[Column3]],UTDNOVEMBRO!B:O,14,FALSE) -> BITOLA DO CABO NA DERIVAÇÃO É MAIOR. E NAO POSSUI CONEC. ESTRIBO. | Y15: =VLOOKUP(pub?gid_1064752002_single_true_output_csv[[#This Row],[Column3]],UTDNOVEMBRO!B:P,15,FALSE) -> 13/10/25 | Z15: =VLOOKUP(pub?gid_1064752002_single_true_output_csv[[#This Row],[Column3]],UTDNOVEMBRO!B:Q,15,FALSE) -> 13/10/25
A16: WILIAN SILVA | B16: DJALMA | C16: B-1227809 | D16: ER-CIND-POV-ASSENTAMENTO SERRA AZUL-SERR | E16: JOÃO DOURADO | F16: QLP | G16: N3 PARA N4 EM POSTE EXISTENTE EM REDE 3X04 13,8Kv | H16: 29 | I16: 03/11/2025 | J16: 14/11/2025 | K16: ATUANDO | L16: CAVA EM ROCHA | M16: LV | O16: 14 | P16: 3 | Q16: =VLOOKUP(pub?gid_1064752002_single_true_output_csv[[#This Row],[Column3]],UTDNOVEMBRO!B:AQ,42,FALSE) -> -11,156158 | R16: =VLOOKUP(pub?gid_1064752002_single_true_output_csv[[#This Row],[Column3]],UTDNOVEMBRO!B:AU,43,FALSE) -> -41,404053 | S16: =VLOOKUP(pub?gid_1064752002_single_true_output_csv[[#This Row],[Column3]],UTDNOVEMBRO!B:AC,28,FALSE) -> 1 | T16: =VLOOKUP(pub?gid_1064752002_single_true_output_csv[[#This Row],[Column3]],UTDNOVEMBRO!B:C,2,FALSE) | U16: =VLOOKUP(pub?gid_1064752002_single_true_output_csv[[#This Row],[Column3]],UTDNOVEMBRO!B:D,3,FALSE) | V16: =VLOOKUP(pub?gid_1064752002_single_true_output_csv[[#This Row],[Column3]],UTDNOVEMBRO!B:K,10,FALSE) -> PEDRO ANDERSON NERI DE SOUZA - U465037 | W16: =VLOOKUP(pub?gid_1064752002_single_true_output_csv[[#This Row],[Column3]],UTDNOVEMBRO!B:N,13,FALSE) -> 09/10/25 | X16: =VLOOKUP(pub?gid_1064752002_single_true_output_csv[[#This Row],[Column3]],UTDNOVEMBRO!B:O,14,FALSE) -> JA EXISTE UMA OBRA SAINDO DA DERIVAÇÃO EM QUESTAO QUE AINDA ESTA EM EXECUÇÃO, POREM, NA PRIMEIRA N3-3 AO INVES DE IR PRA ESQUERDA VAI PRA DIREITA. | Y16: =VLOOKUP(pub?gid_1064752002_single_true_output_csv[[#This Row],[Column3]],UTDNOVEMBRO!B:P,15,FALSE) -> 21/10/25 | Z16: =VLOOKUP(pub?gid_1064752002_single_true_output_csv[[#This Row],[Column3]],UTDNOVEMBRO!B:Q,15,FALSE) -> 21/10/25
A17: IRISMAR | B17: HIAGO | C17: B-1228895 | D17: ER-CIND-POV-LADEIRA VERMELHA-RURAL | E17: CANARANA | F17: QLP | G17: ENERGIZADA | H17: 3 | I17: 04/11/2025 | J17: 04/11/2025 | K17: ENERGIZADA | O17: 3 | P17: 3 | Q17: =VLOOKUP(pub?gid_1064752002_single_true_output_csv[[#This Row],[Column3]],UTDNOVEMBRO!B:AQ,42,FALSE) -> -11.831079 | R17: =VLOOKUP(pub?gid_1064752002_single_true_output_csv[[#This Row],[Column3]],UTDNOVEMBRO!B:AU,43,FALSE) -> -41.74908 | S17: =VLOOKUP(pub?gid_1064752002_single_true_output_csv[[#This Row],[Column3]],UTDNOVEMBRO!B:AC,28,FALSE) -> 1 | T17: =VLOOKUP(pub?gid_1064752002_single_true_output_csv[[#This Row],[Column3]],UTDNOVEMBRO!B:C,2,FALSE) -> N/A | U17: =VLOOKUP(pub?gid_1064752002_single_true_output_csv[[#This Row],[Column3]],UTDNOVEMBRO!B:D,3,FALSE) -> N/A | V17: =VLOOKUP(pub?gid_1064752002_single_true_output_csv[[#This Row],[Column3]],UTDNOVEMBRO!B:K,10,FALSE) -> MANOEL MESSIAS ALENCAR - U359765 | W17: =VLOOKUP(pub?gid_1064752002_single_true_output_csv[[#This Row],[Column3]],UTDNOVEMBRO!B:N,13,FALSE) -> 15/10/25 | X17: =VLOOKUP(pub?gid_1064752002_single_true_output_csv[[#This Row],[Column3]],UTDNOVEMBRO!B:O,14,FALSE) -> ENCABEÇAR REDE CONFORME PROJETO | Y17: =VLOOKUP(pub?gid_1064752002_single_true_output_csv[[#This Row],[Column3]],UTDNOVEMBRO!B:P,15,FALSE) -> 17/10/25 | Z17: =VLOOKUP(pub?gid_1064752002_single_true_output_csv[[#This Row],[Column3]],UTDNOVEMBRO!B:Q,15,FALSE) -> 17/10/25
A18: FELIPE | B18: RENATO | C18: B-1227844 | D18: AC-CIND-POV-PAU D ARCO 69-RURAL | E18: CENTRAL | F18: QLP | G18: ENERGIZADA | H18: 4 | I18: 03/11/2025 | J18: 03/11/2025 | K18: ENERGIZADA | O18: 4 | P18: 4 | Q18: =VLOOKUP(pub?gid_1064752002_single_true_output_csv[[#This Row],[Column3]],UTDNOVEMBRO!B:AQ,42,FALSE) -> -11,057811 | R18: =VLOOKUP(pub?gid_1064752002_single_true_output_csv[[#This Row],[Column3]],UTDNOVEMBRO!B:AU,43,FALSE) -> -42,155731 | S18: =VLOOKUP(pub?gid_1064752002_single_true_output_csv[[#This Row],[Column3]],UTDNOVEMBRO!B:AC,28,FALSE) -> 1 | T18: =VLOOKUP(pub?gid_1064752002_single_true_output_csv[[#This Row],[Column3]],UTDNOVEMBRO!B:C,2,FALSE) -> N/A | U18: =VLOOKUP(pub?gid_1064752002_single_true_output_csv[[#This Row],[Column3]],UTDNOVEMBRO!B:D,3,FALSE) -> N/A | V18: =VLOOKUP(pub?gid_1064752002_single_true_output_csv[[#This Row],[Column3]],UTDNOVEMBRO!B:K,10,FALSE) -> JARBAS LIMA VIEIRA - U348612 | W18: =VLOOKUP(pub?gid_1064752002_single_true_output_csv[[#This Row],[Column3]],UTDNOVEMBRO!B:N,13,FALSE) -> 14/10/25 | X18: =VLOOKUP(pub?gid_1064752002_single_true_output_csv[[#This Row],[Column3]],UTDNOVEMBRO!B:O,14,FALSE) -> OBRA APITA PARA CONSTRUÇÃO CONFORME PROJETO | Y18: =VLOOKUP(pub?gid_1064752002_single_true_output_csv[[#This Row],[Column3]],UTDNOVEMBRO!B:P,15,FALSE) -> 15/10/25 | Z18: =VLOOKUP(pub?gid_1064752002_single_true_output_csv[[#This Row],[Column3]],UTDNOVEMBRO!B:Q,15,FALSE) -> 15/10/25
A19: FELIPE | B19: RENATO | C19: B-1228890 | D19: ER-CIND-POV-ROCADINHO-RURAL | E19: CENTRAL | F19: QLP | G19: ENERGIZADA | H19: 6 | I19: 04/11/2025 | J19: 05/11/2025 | K19: ENERGIZADA | O19: 6 | P19: 6 | Q19: =VLOOKUP(pub?gid_1064752002_single_true_output_csv[[#This Row],[Column3]],UTDNOVEMBRO!B:AQ,42,FALSE) -> -11.139252 | R19: =VLOOKUP(pub?gid_1064752002_single_true_output_csv[[#This Row],[Column3]],UTDNOVEMBRO!B:AU,43,FALSE) -> -42.05577 | S19: =VLOOKUP(pub?gid_1064752002_single_true_output_csv[[#This Row],[Column3]],UTDNOVEMBRO!B:AC,28,FALSE) -> 1 | T19: =VLOOKUP(pub?gid_1064752002_single_true_output_csv[[#This Row],[Column3]],UTDNOVEMBRO!B:C,2,FALSE) -> N/A | U19: =VLOOKUP(pub?gid_1064752002_single_true_output_csv[[#This Row],[Column3]],UTDNOVEMBRO!B:D,3,FALSE) -> N/A | V19: =VLOOKUP(pub?gid_1064752002_single_true_output_csv[[#This Row],[Column3]],UTDNOVEMBRO!B:K,10,FALSE) -> JARBAS LIMA VIEIRA - U348612 | W19: =VLOOKUP(pub?gid_1064752002_single_true_output_csv[[#This Row],[Column3]],UTDNOVEMBRO!B:N,13,FALSE) -> 14/10/25 | X19: =VLOOKUP(pub?gid_1064752002_single_true_output_csv[[#This Row],[Column3]],UTDNOVEMBRO!B:O,14,FALSE) -> OBRA APITA PARA CONSTRUÇÃO CONFORME PROJETO | Y19: =VLOOKUP(pub?gid_1064752002_single_true_output_csv[[#This Row],[Column3]],UTDNOVEMBRO!B:P,15,FALSE) -> 16/10/25 | Z19: =VLOOKUP(pub?gid_1064752002_single_true_output_csv[[#This Row],[Column3]],UTDNOVEMBRO!B:Q,15,FALSE) -> 16/10/25
A20: ENES | B20: RENATO | C20: B-1231419 | D20: ER-CIND-FAZ-BELA VISTA-RURAL | E20: PRESIDENTE DUTRA | F20: QLP | G20: N3 PARA N4 EM POSTE EXISTENTE EM REDE 3X04 13,8Kv | H20: 23 | I20: 04/11/2025 | J20: 30/11/2025 | K20: ATUANDO | M20: LV | O20: 23 | P20: 0 | Q20: =VLOOKUP(pub?gid_1064752002_single_true_output_csv[[#This Row],[Column3]],UTDNOVEMBRO!B:AQ,42,FALSE) -> -11.392045 | R20: =VLOOKUP(pub?gid_1064752002_single_true_output_csv[[#This Row],[Column3]],UTDNOVEMBRO!B:AU,43,FALSE) -> -42.000308 | S20: =VLOOKUP(pub?gid_1064752002_single_true_output_csv[[#This Row],[Column3]],UTDNOVEMBRO!B:AC,28,FALSE) -> 1 | T20: =VLOOKUP(pub?gid_1064752002_single_true_output_csv[[#This Row],[Column3]],UTDNOVEMBRO!B:C,2,FALSE) -> B-1235122 | U20: =VLOOKUP(pub?gid_1064752002_single_true_output_csv[[#This Row],[Column3]],UTDNOVEMBRO!B:D,3,FALSE) -> B-1235135 | V20: =VLOOKUP(pub?gid_1064752002_single_true_output_csv[[#This Row],[Column3]],UTDNOVEMBRO!B:K,10,FALSE) -> JARBAS LIMA VIEIRA - U348612 | W20: =VLOOKUP(pub?gid_1064752002_single_true_output_csv[[#This Row],[Column3]],UTDNOVEMBRO!B:N,13,FALSE) -> 27/10/25 | X20: =VLOOKUP(pub?gid_1064752002_single_true_output_csv[[#This Row],[Column3]],UTDNOVEMBRO!B:O,14,FALSE) -> OBRA APITA PARA CONSTRUÇÃO, | Y20: =VLOOKUP(pub?gid_1064752002_single_true_output_csv[[#This Row],[Column3]],UTDNOVEMBRO!B:P,15,FALSE) -> 27/10/25 | Z20: =VLOOKUP(pub?gid_1064752002_single_true_output_csv[[#This Row],[Column3]],UTDNOVEMBRO!B:Q,15,FALSE) -> 27/10/25
A21: JARBAS | B21: HIAGO | C21: B-1214286 | D21: ER-CIND-POV-MELADOR 25461-MELADOR | E21: CANARANA | F21: QLP | G21: DP 20/11 - ADF EM REDE 3X04 13,8Kv - TR 30KvA 34,5Kv | H21: 15 | I21: 04/11/2025 | J21: 20/11/2025 | K21: ATUANDO | M21: DP/LV | N21: REALIZADO | O21: 15 | P21: 15 | Q21: =VLOOKUP(pub?gid_1064752002_single_true_output_csv[[#This Row],[Column3]],UTDNOVEMBRO!B:AQ,42,FALSE) -> -11,907336 | R21: =VLOOKUP(pub?gid_1064752002_single_true_output_csv[[#This Row],[Column3]],UTDNOVEMBRO!B:AU,43,FALSE) -> -41,702260 | S21: =VLOOKUP(pub?gid_1064752002_single_true_output_csv[[#This Row],[Column3]],UTDNOVEMBRO!B:AC,28,FALSE) -> 0 | T21: =VLOOKUP(pub?gid_1064752002_single_true_output_csv[[#This Row],[Column3]],UTDNOVEMBRO!B:C,2,FALSE) | U21: =VLOOKUP(pub?gid_1064752002_single_true_output_csv[[#This Row],[Column3]],UTDNOVEMBRO!B:D,3,FALSE) | V21: =VLOOKUP(pub?gid_1064752002_single_true_output_csv[[#This Row],[Column3]],UTDNOVEMBRO!B:K,10,FALSE) -> MANOEL MESSIAS ALENCAR - U359765 | W21: =VLOOKUP(pub?gid_1064752002_single_true_output_csv[[#This Row],[Column3]],UTDNOVEMBRO!B:N,13,FALSE) -> 08/10/25 | X21: =VLOOKUP(pub?gid_1064752002_single_true_output_csv[[#This Row],[Column3]],UTDNOVEMBRO!B:O,14,FALSE) -> ADICIONAR FASE CONFORME PROJETO. | Y21: =VLOOKUP(pub?gid_1064752002_single_true_output_csv[[#This Row],[Column3]],UTDNOVEMBRO!B:P,15,FALSE) -> 09/10/25 | Z21: =VLOOKUP(pub?gid_1064752002_single_true_output_csv[[#This Row],[Column3]],UTDNOVEMBRO!B:Q,15,FALSE) -> 09/10/25
A22: MARCOS PAULO | B22: HIAGO | C22: B-1228814 | D22: AC-CIND-POV-VELAME-RURAL | E22: IBIPEBA | F22: QLP | G22: DP 14/11 - ADF SUBSTITUIÇÃO DE TR 10KvA POR 30KvA E CONDUTOR DE BT | H22: 0 | I22: 14/11/2025 | J22: 14/11/2025 | K22: PROGRAMADA | M22: DP | O22: 0 | P22: 0 | Q22: =VLOOKUP(pub?gid_1064752002_single_true_output_csv[[#This Row],[Column3]],UTDNOVEMBRO!B:AQ,42,FALSE) -> -11.449132 | R22: =VLOOKUP(pub?gid_1064752002_single_true_output_csv[[#This Row],[Column3]],UTDNOVEMBRO!B:AU,43,FALSE) -> -42.262552 | S22: =VLOOKUP(pub?gid_1064752002_single_true_output_csv[[#This Row],[Column3]],UTDNOVEMBRO!B:AC,28,FALSE) -> 0 | T22: =VLOOKUP(pub?gid_1064752002_single_true_output_csv[[#This Row],[Column3]],UTDNOVEMBRO!B:C,2,FALSE) -> N/A | U22: =VLOOKUP(pub?gid_1064752002_single_true_output_csv[[#This Row],[Column3]],UTDNOVEMBRO!B:D,3,FALSE) -> N/A | V22: =VLOOKUP(pub?gid_1064752002_single_true_output_csv[[#This Row],[Column3]],UTDNOVEMBRO!B:K,10,FALSE) -> ALINE LIMA SILVA - U468383 | W22: =VLOOKUP(pub?gid_1064752002_single_true_output_csv[[#This Row],[Column3]],UTDNOVEMBRO!B:N,13,FALSE) -> 23/10/25 | X22: =VLOOKUP(pub?gid_1064752002_single_true_output_csv[[#This Row],[Column3]],UTDNOVEMBRO!B:O,14,FALSE) -> OBRA APITAR PARA CONSTRUÇÃO CONFORME PROJETO. | Y22: =VLOOKUP(pub?gid_1064752002_single_true_output_csv[[#This Row],[Column3]],UTDNOVEMBRO!B:P,15,FALSE) -> 24/10/25 | Z22: =VLOOKUP(pub?gid_1064752002_single_true_output_csv[[#This Row],[Column3]],UTDNOVEMBRO!B:Q,15,FALSE) -> 24/10/25
A23: EDIMILSON | B23: HIAGO | C23: B-1228709 | D23: ER-CIND-POV-LAGOA DO ESTEVAO-RURAL | E23: IBITITÁ | F23: QLP | G23: ENERGIZADA | H23: 4 | I23: 03/11/2025 | J23: 03/11/2025 | K23: ENERGIZADA | O23: 4 | P23: 4 | Q23: =VLOOKUP(pub?gid_1064752002_single_true_output_csv[[#This Row],[Column3]],UTDNOVEMBRO!B:AQ,42,FALSE) -> -11,595705 | R23: =VLOOKUP(pub?gid_1064752002_single_true_output_csv[[#This Row],[Column3]],UTDNOVEMBRO!B:AU,43,FALSE) -> -41,855320 | S23: =VLOOKUP(pub?gid_1064752002_single_true_output_csv[[#This Row],[Column3]],UTDNOVEMBRO!B:AC,28,FALSE) -> 1 | T23: =VLOOKUP(pub?gid_1064752002_single_true_output_csv[[#This Row],[Column3]],UTDNOVEMBRO!B:C,2,FALSE) -> B-1235745 | U23: =VLOOKUP(pub?gid_1064752002_single_true_output_csv[[#This Row],[Column3]],UTDNOVEMBRO!B:D,3,FALSE) -> B-1235750 | V23: =VLOOKUP(pub?gid_1064752002_single_true_output_csv[[#This Row],[Column3]],UTDNOVEMBRO!B:K,10,FALSE) -> ALINE LIMA SILVA - U468383 | W23: =VLOOKUP(pub?gid_1064752002_single_true_output_csv[[#This Row],[Column3]],UTDNOVEMBRO!B:N,13,FALSE) -> 08/10/25 | X23: =VLOOKUP(pub?gid_1064752002_single_true_output_csv[[#This Row],[Column3]],UTDNOVEMBRO!B:O,14,FALSE) -> OBRA APITA PARA CONSTRUÇÃO.CONFOME PROJETO _x000D_ ENCABEÇAR DE REDE BT_x000D_ | Y23: =VLOOKUP(pub?gid_1064752002_single_true_output_csv[[#This Row],[Column3]],UTDNOVEMBRO!B:P,15,FALSE) -> 09/10/25 | Z23: =VLOOKUP(pub?gid_1064752002_single_true_output_csv[[#This Row],[Column3]],UTDNOVEMBRO!B:Q,15,FALSE) -> 09/10/25
A24: EDIMILSON | B24: HIAGO | C24: B-1230299 | D24: ER-CIND-POV-LAGEDAO-RURAL | E24: IBITITÁ | F24: QLP | G24: DP 14/11 - N3 PARA N3 EM REDE 3X04 13,8Kv | H24: 43 | I24: 04/11/2025 | J24: 30/11/2025 | K24: ATUANDO | M24: DP/LV | N24: 14/11/2025 | O24: 45 | P24: 34 | Q24: =VLOOKUP(pub?gid_1064752002_single_true_output_csv[[#This Row],[Column3]],UTDNOVEMBRO!B:AQ,42,FALSE) -> -11.542334 | R24: =VLOOKUP(pub?gid_1064752002_single_true_output_csv[[#This Row],[Column3]],UTDNOVEMBRO!B:AU,43,FALSE) -> -41.883423 | S24: =VLOOKUP(pub?gid_1064752002_single_true_output_csv[[#This Row],[Column3]],UTDNOVEMBRO!B:AC,28,FALSE) -> 2 | T24: =VLOOKUP(pub?gid_1064752002_single_true_output_csv[[#This Row],[Column3]],UTDNOVEMBRO!B:C,2,FALSE) -> CRIAR | U24: =VLOOKUP(pub?gid_1064752002_single_true_output_csv[[#This Row],[Column3]],UTDNOVEMBRO!B:D,3,FALSE) -> CRIAR | V24: =VLOOKUP(pub?gid_1064752002_single_true_output_csv[[#This Row],[Column3]],UTDNOVEMBRO!B:K,10,FALSE) -> ALINE LIMA SILVA - U468383 | W24: =VLOOKUP(pub?gid_1064752002_single_true_output_csv[[#This Row],[Column3]],UTDNOVEMBRO!B:N,13,FALSE) -> 17/10/25 | X24: =VLOOKUP(pub?gid_1064752002_single_true_output_csv[[#This Row],[Column3]],UTDNOVEMBRO!B:O,14,FALSE) -> OBRA APITAR PARA CONSTRUÇÃO CONFORME PROJETO. | Y24: =VLOOKUP(pub?gid_1064752002_single_true_output_csv[[#This Row],[Column3]],UTDNOVEMBRO!B:P,15,FALSE) -> 20/10/25 | Z24: =VLOOKUP(pub?gid_1064752002_single_true_output_csv[[#This Row],[Column3]],UTDNOVEMBRO!B:Q,15,FALSE) -> 20/10/25
A25: REVERTON | B25: RENATO | C25: B-1212255 | D25: ER-CIND-POV-VARIANTE-RURAL | E25: SÃO GABRIEL | F25: QLP | G25: ENERGIZADA | H25: 7 | I25: 04/11/2025 | J25: 06/11/2025 | K25: ENERGIZADA | M25: LV | N25: REALIZADO | O25: 7 | P25: 7 | Q25: =VLOOKUP(pub?gid_1064752002_single_true_output_csv[[#This Row],[Column3]],UTDNOVEMBRO!B:AQ,42,FALSE) -> -11,174356 | R25: =VLOOKUP(pub?gid_1064752002_single_true_output_csv[[#This Row],[Column3]],UTDNOVEMBRO!B:AU,43,FALSE) -> -41,803870 | S25: =VLOOKUP(pub?gid_1064752002_single_true_output_csv[[#This Row],[Column3]],UTDNOVEMBRO!B:AC,28,FALSE) -> 1 | T25: =VLOOKUP(pub?gid_1064752002_single_true_output_csv[[#This Row],[Column3]],UTDNOVEMBRO!B:C,2,FALSE) -> B-1235744 | U25: =VLOOKUP(pub?gid_1064752002_single_true_output_csv[[#This Row],[Column3]],UTDNOVEMBRO!B:D,3,FALSE) -> B-1235749 | V25: =VLOOKUP(pub?gid_1064752002_single_true_output_csv[[#This Row],[Column3]],UTDNOVEMBRO!B:K,10,FALSE) -> FLAVIO ALMEIDA DOS ANJOS - U468839 | W25: =VLOOKUP(pub?gid_1064752002_single_true_output_csv[[#This Row],[Column3]],UTDNOVEMBRO!B:N,13,FALSE) -> 21/10/25 | X25: =VLOOKUP(pub?gid_1064752002_single_true_output_csv[[#This Row],[Column3]],UTDNOVEMBRO!B:O,14,FALSE) -> ALTERAR DERIVAÇÃO. MONTAR ESTRUTURA N3 NO PG E855712 E MONTAR N4 COM CHAVE NO PONTO 05. | Y25: =VLOOKUP(pub?gid_1064752002_single_true_output_csv[[#This Row],[Column3]],UTDNOVEMBRO!B:P,15,FALSE) -> 27/10/25 | Z25: =VLOOKUP(pub?gid_1064752002_single_true_output_csv[[#This Row],[Column3]],UTDNOVEMBRO!B:Q,15,FALSE) -> 27/10/25
A26: WILIAN SILVA, UBERDAN | B26: DJALMA | C26: B-1226260 | D26: ER-CIND-POV-MATA DO MILHO-CENTRO | E26: JOÃO DOURADO | F26: QLP | G26: N3 PARA N4 EM POSTE EXISTENTE EM REDE 3X04 13,8Kv | H26: 21 | I26: 17/11/2025 | J26: 30/11/2025 | K26: PROGRAMADA | L26: CAVA EM ROCHA | M26: LV | O26: 11 | P26: 2 | Q26: =VLOOKUP(pub?gid_1064752002_single_true_output_csv[[#This Row],[Column3]],UTDNOVEMBRO!B:AQ,42,FALSE) -> -11,182657 | R26: =VLOOKUP(pub?gid_1064752002_single_true_output_csv[[#This Row],[Column3]],UTDNOVEMBRO!B:AU,43,FALSE) -> -41,397356 | S26: =VLOOKUP(pub?gid_1064752002_single_true_output_csv[[#This Row],[Column3]],UTDNOVEMBRO!B:AC,28,FALSE) -> 3 | T26: =VLOOKUP(pub?gid_1064752002_single_true_output_csv[[#This Row],[Column3]],UTDNOVEMBRO!B:C,2,FALSE) | U26: =VLOOKUP(pub?gid_1064752002_single_true_output_csv[[#This Row],[Column3]],UTDNOVEMBRO!B:D,3,FALSE) | V26: =VLOOKUP(pub?gid_1064752002_single_true_output_csv[[#This Row],[Column3]],UTDNOVEMBRO!B:K,10,FALSE) -> PEDRO ANDERSON NERI DE SOUZA - U465037 | W26: =VLOOKUP(pub?gid_1064752002_single_true_output_csv[[#This Row],[Column3]],UTDNOVEMBRO!B:N,13,FALSE) -> 09/10/25 | X26: =VLOOKUP(pub?gid_1064752002_single_true_output_csv[[#This Row],[Column3]],UTDNOVEMBRO!B:O,14,FALSE) -> INTERCALAR POSTE MT 11/600 NO OUTRO LADO DA CERCA. POIS SE TRANSFORMAR A EXISTENTE EM N4 VAI SAIR MUITO TORTA POR CONTA DO POSTE DT. | Y26: =VLOOKUP(pub?gid_1064752002_single_true_output_csv[[#This Row],[Column3]],UTDNOVEMBRO!B:P,15,FALSE) -> 13/10/25 | Z26: =VLOOKUP(pub?gid_1064752002_single_true_output_csv[[#This Row],[Column3]],UTDNOVEMBRO!B:Q,15,FALSE) -> 13/10/25
A27: VANILSON | B27: DJALMA | C27: B-1228556 | D27: ER-CIND-POV-LAGOA DOS LUNDUS-RURAL | E27: JOÃO DOURADO | F27: QLP | G27: INTERCALAR POSTE 11/600 N1 - N3 CF EM REDE 3X04 13,8Kv - CAVA COM RETRO | H27: 13 | I27: 13/11/2025 | J27: 19/11/2025 | K27: ATUANDO | L27: CAVA EM ROCHA | M27: LV | O27: 0 | P27: 0 | Q27: =VLOOKUP(pub?gid_1064752002_single_true_output_csv[[#This Row],[Column3]],UTDNOVEMBRO!B:AQ,42,FALSE) -> -11,158357 | R27: =VLOOKUP(pub?gid_1064752002_single_true_output_csv[[#This Row],[Column3]],UTDNOVEMBRO!B:AU,43,FALSE) -> -41,453961 | S27: =VLOOKUP(pub?gid_1064752002_single_true_output_csv[[#This Row],[Column3]],UTDNOVEMBRO!B:AC,28,FALSE) -> 1 | T27: =VLOOKUP(pub?gid_1064752002_single_true_output_csv[[#This Row],[Column3]],UTDNOVEMBRO!B:C,2,FALSE) | U27: =VLOOKUP(pub?gid_1064752002_single_true_output_csv[[#This Row],[Column3]],UTDNOVEMBRO!B:D,3,FALSE) | V27: =VLOOKUP(pub?gid_1064752002_single_true_output_csv[[#This Row],[Column3]],UTDNOVEMBRO!B:K,10,FALSE) -> PEDRO ANDERSON NERI DE SOUZA - U465037 | W27: =VLOOKUP(pub?gid_1064752002_single_true_output_csv[[#This Row],[Column3]],UTDNOVEMBRO!B:N,13,FALSE) -> 09/10/25 | X27: =VLOOKUP(pub?gid_1064752002_single_true_output_csv[[#This Row],[Column3]],UTDNOVEMBRO!B:O,14,FALSE) -> NTERCALAR POSTE MT 11/600 NO PONTO 01 CONFORME PROJETO. | Y27: =VLOOKUP(pub?gid_1064752002_single_true_output_csv[[#This Row],[Column3]],UTDNOVEMBRO!B:P,15,FALSE) -> 13/10/25 | Z27: =VLOOKUP(pub?gid_1064752002_single_true_output_csv[[#This Row],[Column3]],UTDNOVEMBRO!B:Q,15,FALSE) -> 13/10/25
A28: ALAN | B28: DJALMA | C28: B-1228748 | D28: AC-CIND-PR -DA IGREJA-RURAL | E28: LAPÃO | F28: QLP | G28: ENERGIZADA | H28: 0 | I28: 11/11/2025 | J28: 11/11/2025 | K28: ENERGIZADA | M28: DP | O28: 0 | P28: 0 | Q28: =VLOOKUP(pub?gid_1064752002_single_true_output_csv[[#This Row],[Column3]],UTDNOVEMBRO!B:AQ,42,FALSE) -> -11,476205 | R28: =VLOOKUP(pub?gid_1064752002_single_true_output_csv[[#This Row],[Column3]],UTDNOVEMBRO!B:AU,43,FALSE) -> -41,770260 | S28: =VLOOKUP(pub?gid_1064752002_single_true_output_csv[[#This Row],[Column3]],UTDNOVEMBRO!B:AC,28,FALSE) -> 0 | T28: =VLOOKUP(pub?gid_1064752002_single_true_output_csv[[#This Row],[Column3]],UTDNOVEMBRO!B:C,2,FALSE) -> N/A | U28: =VLOOKUP(pub?gid_1064752002_single_true_output_csv[[#This Row],[Column3]],UTDNOVEMBRO!B:D,3,FALSE) -> N/A | V28: =VLOOKUP(pub?gid_1064752002_single_true_output_csv[[#This Row],[Column3]],UTDNOVEMBRO!B:K,10,FALSE) -> JHONATAN MARANHAO - U617542 | W28: =VLOOKUP(pub?gid_1064752002_single_true_output_csv[[#This Row],[Column3]],UTDNOVEMBRO!B:N,13,FALSE) -> 08/10/25 | X28: =VLOOKUP(pub?gid_1064752002_single_true_output_csv[[#This Row],[Column3]],UTDNOVEMBRO!B:O,14,FALSE) -> VERIFICAR: PROJETO DIVERGE DE CAMPO | Y28: =VLOOKUP(pub?gid_1064752002_single_true_output_csv[[#This Row],[Column3]],UTDNOVEMBRO!B:P,15,FALSE) -> 30/10/25 | Z28: =VLOOKUP(pub?gid_1064752002_single_true_output_csv[[#This Row],[Column3]],UTDNOVEMBRO!B:Q,15,FALSE) -> 30/10/25
A29: ESMERALDO | B29: RENATO | C29: B-1229264 | D29: ER-CIND-POV-LAGOA DO CHICO EDU-RURAL | E29: ITAGUAÇU DA BAHIA | F29: QLP | G29: DP 17/11 - ADF EM TRECHO DE 2,5 KM | H29: 19 | I29: 04/11/2025 | J29: 17/11/2025 | K29: ATUANDO | M29: DP/LV | N29: 17/11/2025 | O29: 20 | P29: 19 | Q29: =VLOOKUP(pub?gid_1064752002_single_true_output_csv[[#This Row],[Column3]],UTDNOVEMBRO!B:AQ,42,FALSE) -> -11,011449 | R29: =VLOOKUP(pub?gid_1064752002_single_true_output_csv[[#This Row],[Column3]],UTDNOVEMBRO!B:AU,43,FALSE) -> -42,293051_x000D_ | S29: =VLOOKUP(pub?gid_1064752002_single_true_output_csv[[#This Row],[Column3]],UTDNOVEMBRO!B:AC,28,FALSE) -> 1 | T29: =VLOOKUP(pub?gid_1064752002_single_true_output_csv[[#This Row],[Column3]],UTDNOVEMBRO!B:C,2,FALSE) -> B-1235763 | U29: =VLOOKUP(pub?gid_1064752002_single_true_output_csv[[#This Row],[Column3]],UTDNOVEMBRO!B:D,3,FALSE) -> B-1235765 | V29: =VLOOKUP(pub?gid_1064752002_single_true_output_csv[[#This Row],[Column3]],UTDNOVEMBRO!B:K,10,FALSE) -> JOSE EDUARDO GOMES DOS SANTOS LIMA - U468835 | W29: =VLOOKUP(pub?gid_1064752002_single_true_output_csv[[#This Row],[Column3]],UTDNOVEMBRO!B:N,13,FALSE) -> 23/10/25 | X29: =VLOOKUP(pub?gid_1064752002_single_true_output_csv[[#This Row],[Column3]],UTDNOVEMBRO!B:O,14,FALSE) -> ADF DE ACORDO PROJETO | Y29: =VLOOKUP(pub?gid_1064752002_single_true_output_csv[[#This Row],[Column3]],UTDNOVEMBRO!B:P,15,FALSE) -> 23/10/25 | Z29: =VLOOKUP(pub?gid_1064752002_single_true_output_csv[[#This Row],[Column3]],UTDNOVEMBRO!B:Q,15,FALSE) -> 23/10/25
A30: ALAN | B30: DJALMA | C30: B-1211158 | D30: ER-CIND-FAZ-GUARANY-RURAL | E30: AMÉRICA DOURADA | F30: QLP | G30: INTERCALAR POSTE 11/600 N1-B3M EM REDE 2X04 13,8Kv | H30: 23 | I30: 05/11/2025 | J30: 17/11/2025 | K30: ATUANDO | M30: LV | N30: REALIZADO | O30: 24 | P30: 25 | Q30: =VLOOKUP(pub?gid_1064752002_single_true_output_csv[[#This Row],[Column3]],UTDNOVEMBRO!B:AQ,42,FALSE) -> -11,431598 | R30: =VLOOKUP(pub?gid_1064752002_single_true_output_csv[[#This Row],[Column3]],UTDNOVEMBRO!B:AU,43,FALSE) -> -41,602491 | S30: =VLOOKUP(pub?gid_1064752002_single_true_output_csv[[#This Row],[Column3]],UTDNOVEMBRO!B:AC,28,FALSE) -> 2 | T30: =VLOOKUP(pub?gid_1064752002_single_true_output_csv[[#This Row],[Column3]],UTDNOVEMBRO!B:C,2,FALSE) -> N/A | U30: =VLOOKUP(pub?gid_1064752002_single_true_output_csv[[#This Row],[Column3]],UTDNOVEMBRO!B:D,3,FALSE) -> N/A | V30: =VLOOKUP(pub?gid_1064752002_single_true_output_csv[[#This Row],[Column3]],UTDNOVEMBRO!B:K,10,FALSE) -> JOSE ANTONIO SIMAS NETO - U349485 | W30: =VLOOKUP(pub?gid_1064752002_single_true_output_csv[[#This Row],[Column3]],UTDNOVEMBRO!B:N,13,FALSE) -> 09/10/25 | X30: =VLOOKUP(pub?gid_1064752002_single_true_output_csv[[#This Row],[Column3]],UTDNOVEMBRO!B:O,14,FALSE) -> INTERCALAR POSTE MT 11/600 ENTRE OS POSTES E765100 E O E765101 | Y30: =VLOOKUP(pub?gid_1064752002_single_true_output_csv[[#This Row],[Column3]],UTDNOVEMBRO!B:P,15,FALSE) -> 09/10/25 | Z30: =VLOOKUP(pub?gid_1064752002_single_true_output_csv[[#This Row],[Column3]],UTDNOVEMBRO!B:Q,15,FALSE) -> 09/10/25
A31: JARBAS | B31: HIAGO | C31: B-1228504 | D31: ER-CIND-POV-DESCOBERTO-RURAL | E31: CANARANA | F31: QLP | G31: N3 PARA N4 EM POSTE EXISTENTE EM REDE 2X04 13,8Kv - MUDAR COD. CELA CRUZETA | H31: 17 | I31: 06/11/2025 | J31: 14/11/2025 | K31: ATUANDO | M31: LV | O31: 17 | P31: 8 | Q31: =VLOOKUP(pub?gid_1064752002_single_true_output_csv[[#This Row],[Column3]],UTDNOVEMBRO!B:AQ,42,FALSE) -> -11,908580 | R31: =VLOOKUP(pub?gid_1064752002_single_true_output_csv[[#This Row],[Column3]],UTDNOVEMBRO!B:AU,43,FALSE) -> -41,675359 | S31: =VLOOKUP(pub?gid_1064752002_single_true_output_csv[[#This Row],[Column3]],UTDNOVEMBRO!B:AC,28,FALSE) -> 1 | T31: =VLOOKUP(pub?gid_1064752002_single_true_output_csv[[#This Row],[Column3]],UTDNOVEMBRO!B:C,2,FALSE) | U31: =VLOOKUP(pub?gid_1064752002_single_true_output_csv[[#This Row],[Column3]],UTDNOVEMBRO!B:D,3,FALSE) | V31: =VLOOKUP(pub?gid_1064752002_single_true_output_csv[[#This Row],[Column3]],UTDNOVEMBRO!B:K,10,FALSE) -> MANOEL MESSIAS ALENCAR - U359765 | W31: =VLOOKUP(pub?gid_1064752002_single_true_output_csv[[#This Row],[Column3]],UTDNOVEMBRO!B:N,13,FALSE) -> 08/10/25 | X31: =VLOOKUP(pub?gid_1064752002_single_true_output_csv[[#This Row],[Column3]],UTDNOVEMBRO!B:O,14,FALSE) -> ALTERAR ESTRUTURA MT DE M3 PRA M4 NO PG DO TRAFO H35248. | Y31: =VLOOKUP(pub?gid_1064752002_single_true_output_csv[[#This Row],[Column3]],UTDNOVEMBRO!B:P,15,FALSE) -> 28/10/25 | Z31: =VLOOKUP(pub?gid_1064752002_single_true_output_csv[[#This Row],[Column3]],UTDNOVEMBRO!B:Q,15,FALSE) -> 28/10/25
A32: MARCOS PAULO | B32: HIAGO | C32: B-1182565 | D32: AC-COEL-RUA-ANTERO VIEIRA-CENTRO | E32: IBIPEBA | F32: INSTITUCIONAL | G32: DP 18/11 - ADF N3 PARA N4 EM POSTE EXISTENTE EM REDE 3x04 13,8Kv | H32: 17 | I32: 12/11/2025 | J32: 18/11/2025 | K32: ATUANDO | M32: DP/LV | N32: 18/11/2025 | O32: 17 | P32: 3 | Q32: =VLOOKUP(pub?gid_1064752002_single_true_output_csv[[#This Row],[Column3]],UTDNOVEMBRO!B:AQ,42,FALSE) -> -11,489303 | R32: =VLOOKUP(pub?gid_1064752002_single_true_output_csv[[#This Row],[Column3]],UTDNOVEMBRO!B:AU,43,FALSE) -> -42,273487 | S32: =VLOOKUP(pub?gid_1064752002_single_true_output_csv[[#This Row],[Column3]],UTDNOVEMBRO!B:AC,28,FALSE) -> 0 | T32: =VLOOKUP(pub?gid_1064752002_single_true_output_csv[[#This Row],[Column3]],UTDNOVEMBRO!B:C,2,FALSE) | U32: =VLOOKUP(pub?gid_1064752002_single_true_output_csv[[#This Row],[Column3]],UTDNOVEMBRO!B:D,3,FALSE) | V32: =VLOOKUP(pub?gid_1064752002_single_true_output_csv[[#This Row],[Column3]],UTDNOVEMBRO!B:K,10,FALSE) -> ALINE LIMA SILVA - U468383 | W32: =VLOOKUP(pub?gid_1064752002_single_true_output_csv[[#This Row],[Column3]],UTDNOVEMBRO!B:N,13,FALSE) -> 20/10/25 | X32: =VLOOKUP(pub?gid_1064752002_single_true_output_csv[[#This Row],[Column3]],UTDNOVEMBRO!B:O,14,FALSE) -> OBRA APITAR PARA CONSTRUÇÃO. ADF SEGUE COMFORME PONTOS COLETADO. | Y32: =VLOOKUP(pub?gid_1064752002_single_true_output_csv[[#This Row],[Column3]],UTDNOVEMBRO!B:P,15,FALSE) -> 27/10/25 | Z32: =VLOOKUP(pub?gid_1064752002_single_true_output_csv[[#This Row],[Column3]],UTDNOVEMBRO!B:Q,15,FALSE) -> 27/10/25
A33: GIORLAN | B33: RENATO | C33: B-1228726 | D33: AC-CIND-POV-CAMAROTE-RURAL | E33: UIBAÍ | F33: QLP | G33: ENERGIZADA | H33: 0 | I33: 12/11/2025 | J33: 12/11/2025 | K33: ENERGIZADA | M33: DP | O33: 0 | P33: 0 | Q33: =VLOOKUP(pub?gid_1064752002_single_true_output_csv[[#This Row],[Column3]],UTDNOVEMBRO!B:AQ,42,FALSE) -> -11,355628 | R33: =VLOOKUP(pub?gid_1064752002_single_true_output_csv[[#This Row],[Column3]],UTDNOVEMBRO!B:AU,43,FALSE) -> -42,108336 | S33: =VLOOKUP(pub?gid_1064752002_single_true_output_csv[[#This Row],[Column3]],UTDNOVEMBRO!B:AC,28,FALSE) -> 0 | T33: =VLOOKUP(pub?gid_1064752002_single_true_output_csv[[#This Row],[Column3]],UTDNOVEMBRO!B:C,2,FALSE) -> N/A | U33: =VLOOKUP(pub?gid_1064752002_single_true_output_csv[[#This Row],[Column3]],UTDNOVEMBRO!B:D,3,FALSE) -> N/A | V33: =VLOOKUP(pub?gid_1064752002_single_true_output_csv[[#This Row],[Column3]],UTDNOVEMBRO!B:K,10,FALSE) -> JARBAS LIMA VIEIRA - U348612 | W33: =VLOOKUP(pub?gid_1064752002_single_true_output_csv[[#This Row],[Column3]],UTDNOVEMBRO!B:N,13,FALSE) -> 07/10/2025 | X33: =VLOOKUP(pub?gid_1064752002_single_true_output_csv[[#This Row],[Column3]],UTDNOVEMBRO!B:O,14,FALSE) -> SUBSTITUIR TRAFO CONFORME PROJETO. INFORMAÇÕES DAS ESTRUTURAS ESTÃO NOS PONTOS. | Y33: =VLOOKUP(pub?gid_1064752002_single_true_output_csv[[#This Row],[Column3]],UTDNOVEMBRO!B:P,15,FALSE) -> 08/10/25 | Z33: =VLOOKUP(pub?gid_1064752002_single_true_output_csv[[#This Row],[Column3]],UTDNOVEMBRO!B:Q,15,FALSE) -> 08/10/25
A34: GIORLAN | B34: RENATO | C34: B-1228821 | D34: ER-CIND-POV-HIDROLANDIA-RURAL | E34: UIBAÍ | F34: QLP | G34: ENERGIZADA | H34: 6 | I34: 03/11/2025 | J34: 04/11/2025 | K34: ENERGIZADA | O34: 6 | P34: 6 | Q34: =VLOOKUP(pub?gid_1064752002_single_true_output_csv[[#This Row],[Column3]],UTDNOVEMBRO!B:AQ,42,FALSE) -> -11,249115 | R34: =VLOOKUP(pub?gid_1064752002_single_true_output_csv[[#This Row],[Column3]],UTDNOVEMBRO!B:AU,43,FALSE) -> -42,164449 | S34: =VLOOKUP(pub?gid_1064752002_single_true_output_csv[[#This Row],[Column3]],UTDNOVEMBRO!B:AC,28,FALSE) -> 2 | T34: =VLOOKUP(pub?gid_1064752002_single_true_output_csv[[#This Row],[Column3]],UTDNOVEMBRO!B:C,2,FALSE) -> N/A | U34: =VLOOKUP(pub?gid_1064752002_single_true_output_csv[[#This Row],[Column3]],UTDNOVEMBRO!B:D,3,FALSE) -> N/A | V34: =VLOOKUP(pub?gid_1064752002_single_true_output_csv[[#This Row],[Column3]],UTDNOVEMBRO!B:K,10,FALSE) -> JARBAS LIMA VIEIRA - U348612 | W34: =VLOOKUP(pub?gid_1064752002_single_true_output_csv[[#This Row],[Column3]],UTDNOVEMBRO!B:N,13,FALSE) -> 07/10/2025 | X34: =VLOOKUP(pub?gid_1064752002_single_true_output_csv[[#This Row],[Column3]],UTDNOVEMBRO!B:O,14,FALSE) -> ALTERAR DERIVAÇÃO. | Y34: =VLOOKUP(pub?gid_1064752002_single_true_output_csv[[#This Row],[Column3]],UTDNOVEMBRO!B:P,15,FALSE) -> 08/10/25 | Z34: =VLOOKUP(pub?gid_1064752002_single_true_output_csv[[#This Row],[Column3]],UTDNOVEMBRO!B:Q,15,FALSE) -> 08/10/25
A35: IRISMAR | B35: HIAGO | C35: B-1011861 | D35: IS-COEL-FAZ-SUELI-RURAL | E35: CANARANA | F35: INTERV SEGURANÇA | G35: DP 18/11 E 24/11 - DESATIVAR REDE E INTERLIGAR TECHO NOVO | H35: 11 | I35: 10/11/2025 | J35: 18/11/2025 | K35: ATUANDO | M35: DP | O35: 11 | P35: 3 | Q35: =VLOOKUP(pub?gid_1064752002_single_true_output_csv[[#This Row],[Column3]],UTDNOVEMBRO!B:AQ,42,FALSE) -> -11.701598 | R35: =VLOOKUP(pub?gid_1064752002_single_true_output_csv[[#This Row],[Column3]],UTDNOVEMBRO!B:AU,43,FALSE) -> -41.759803 | S35: =VLOOKUP(pub?gid_1064752002_single_true_output_csv[[#This Row],[Column3]],UTDNOVEMBRO!B:AC,28,FALSE) -> 0 | T35: =VLOOKUP(pub?gid_1064752002_single_true_output_csv[[#This Row],[Column3]],UTDNOVEMBRO!B:C,2,FALSE) | U35: =VLOOKUP(pub?gid_1064752002_single_true_output_csv[[#This Row],[Column3]],UTDNOVEMBRO!B:D,3,FALSE) | V35: =VLOOKUP(pub?gid_1064752002_single_true_output_csv[[#This Row],[Column3]],UTDNOVEMBRO!B:K,10,FALSE) -> MANOEL MESSIAS ALENCAR - U359765 | W35: =VLOOKUP(pub?gid_1064752002_single_true_output_csv[[#This Row],[Column3]],UTDNOVEMBRO!B:N,13,FALSE) -> 15/10/2025 | X35: =VLOOKUP(pub?gid_1064752002_single_true_output_csv[[#This Row],[Column3]],UTDNOVEMBRO!B:O,14,FALSE) -> MONTAR ESTRUTURA B3 NO PG B696749. EM CAMPO JA É N1, MONTAR ESTRUTURAS BECO. PA REDE VAI PASSAR EM FRENTE A LOTES DE CASAS E MUROS JA PRONTOS | Y35: =VLOOKUP(pub?gid_1064752002_single_true_output_csv[[#This Row],[Column3]],UTDNOVEMBRO!B:P,15,FALSE) -> 20/10/25 | Z35: =VLOOKUP(pub?gid_1064752002_single_true_output_csv[[#This Row],[Column3]],UTDNOVEMBRO!B:Q,15,FALSE) -> 20/10/25
A36: FELIPE | B36: RENATO | C36: B-1228949 | D36: ER-CIND-POV-SAO JOAO-DO ZE DA PRETA | E36: CENTRAL | F36: QLP | G36: N3 PARA N3 EM REDE 2X04 13,8Kv | H36: 18 | I36: 06/11/2025 | J36: 14/11/2025 | K36: ATUANDO | M36: LV | N36: 15/11/2025 | O36: 18 | P36: 18 | Q36: =VLOOKUP(pub?gid_1064752002_single_true_output_csv[[#This Row],[Column3]],UTDNOVEMBRO!B:AQ,42,FALSE) -> -11.079716 | R36: =VLOOKUP(pub?gid_1064752002_single_true_output_csv[[#This Row],[Column3]],UTDNOVEMBRO!B:AU,43,FALSE) -> -42.072856 | S36: =VLOOKUP(pub?gid_1064752002_single_true_output_csv[[#This Row],[Column3]],UTDNOVEMBRO!B:AC,28,FALSE) -> 2 | T36: =VLOOKUP(pub?gid_1064752002_single_true_output_csv[[#This Row],[Column3]],UTDNOVEMBRO!B:C,2,FALSE) -> CRIAR | U36: =VLOOKUP(pub?gid_1064752002_single_true_output_csv[[#This Row],[Column3]],UTDNOVEMBRO!B:D,3,FALSE) -> CRIAR | V36: =VLOOKUP(pub?gid_1064752002_single_true_output_csv[[#This Row],[Column3]],UTDNOVEMBRO!B:K,10,FALSE) -> JARBAS LIMA VIEIRA - U348612 | W36: =VLOOKUP(pub?gid_1064752002_single_true_output_csv[[#This Row],[Column3]],UTDNOVEMBRO!B:N,13,FALSE) -> 14/10/25 | X36: =VLOOKUP(pub?gid_1064752002_single_true_output_csv[[#This Row],[Column3]],UTDNOVEMBRO!B:O,14,FALSE) -> OBRA APITA PARA CONSTRUÇÃO CONFORME PROJETO | Y36: =VLOOKUP(pub?gid_1064752002_single_true_output_csv[[#This Row],[Column3]],UTDNOVEMBRO!B:P,15,FALSE) -> 15/10/25 | Z36: =VLOOKUP(pub?gid_1064752002_single_true_output_csv[[#This Row],[Column3]],UTDNOVEMBRO!B:Q,15,FALSE) -> 15/10/25
A37: MARCOS PAULO | B37: HIAGO | C37: B-1140811 | D37: ER-CIND-POV-PLANALTO-RURAL | E37: CANARANA | F37: QLP | G37: DP 25/11 | H37: 7 | I37: 19/11/2025 | J37: 27/11/2025 | K37: PROGRAMADA | M37: DP/LV | O37: 0 | P37: 0 | Q37: =VLOOKUP(pub?gid_1064752002_single_true_output_csv[[#This Row],[Column3]],UTDNOVEMBRO!B:AQ,42,FALSE) -> -11,805420 | R37: =VLOOKUP(pub?gid_1064752002_single_true_output_csv[[#This Row],[Column3]],UTDNOVEMBRO!B:AU,43,FALSE) -> -41,738076 | S37: =VLOOKUP(pub?gid_1064752002_single_true_output_csv[[#This Row],[Column3]],UTDNOVEMBRO!B:AC,28,FALSE) | T37: =VLOOKUP(pub?gid_1064752002_single_true_output_csv[[#This Row],[Column3]],UTDNOVEMBRO!B:C,2,FALSE) | U37: =VLOOKUP(pub?gid_1064752002_single_true_output_csv[[#This Row],[Column3]],UTDNOVEMBRO!B:D,3,FALSE) | V37: =VLOOKUP(pub?gid_1064752002_single_true_output_csv[[#This Row],[Column3]],UTDNOVEMBRO!B:K,10,FALSE) -> MANOEL MESSIAS ALENCAR - U359765 | W37: =VLOOKUP(pub?gid_1064752002_single_true_output_csv[[#This Row],[Column3]],UTDNOVEMBRO!B:N,13,FALSE) -> 22/10/25 | X37: =VLOOKUP(pub?gid_1064752002_single_true_output_csv[[#This Row],[Column3]],UTDNOVEMBRO!B:O,14,FALSE) -> ADICIONAR FASE. INTERCALAR POSTE 12/600 COM FLABIDT +U3 E N1 TRIF. | Y37: =VLOOKUP(pub?gid_1064752002_single_true_output_csv[[#This Row],[Column3]],UTDNOVEMBRO!B:P,15,FALSE) -> 24/10/25 | Z37: =VLOOKUP(pub?gid_1064752002_single_true_output_csv[[#This Row],[Column3]],UTDNOVEMBRO!B:Q,15,FALSE) -> 24/10/25
A38: REVERTON | B38: RENATO | C38: B-1229074 | D38: ER-CIND-POV-VARIANTE-RURAL SAO GABRIEL | E38: SÃO GABRIEL | F38: QLP | G38: N3 PARA N4 EM POSTE EXISTENTE EM REDE 3x04 13.8Kv | H38: 15 | I38: 10/11/2025 | J38: 25/11/2025 | K38: ATUANDO | M38: LV | O38: 8 | P38: 13 | Q38: =VLOOKUP(pub?gid_1064752002_single_true_output_csv[[#This Row],[Column3]],UTDNOVEMBRO!B:AQ,42,FALSE) -> -11,152108 | R38: =VLOOKUP(pub?gid_1064752002_single_true_output_csv[[#This Row],[Column3]],UTDNOVEMBRO!B:AU,43,FALSE) -> -41,801523 | S38: =VLOOKUP(pub?gid_1064752002_single_true_output_csv[[#This Row],[Column3]],UTDNOVEMBRO!B:AC,28,FALSE) -> 2 | T38: =VLOOKUP(pub?gid_1064752002_single_true_output_csv[[#This Row],[Column3]],UTDNOVEMBRO!B:C,2,FALSE) -> CRIAR | U38: =VLOOKUP(pub?gid_1064752002_single_true_output_csv[[#This Row],[Column3]],UTDNOVEMBRO!B:D,3,FALSE) -> CRIAR | V38: =VLOOKUP(pub?gid_1064752002_single_true_output_csv[[#This Row],[Column3]],UTDNOVEMBRO!B:K,10,FALSE) -> FLAVIO ALMEIDA DOS ANJOS - U468839 | W38: =VLOOKUP(pub?gid_1064752002_single_true_output_csv[[#This Row],[Column3]],UTDNOVEMBRO!B:N,13,FALSE) -> 21/10/25 | X38: =VLOOKUP(pub?gid_1064752002_single_true_output_csv[[#This Row],[Column3]],UTDNOVEMBRO!B:O,14,FALSE) -> ENCABECAR REDE CONFORME PROJETO E SUBSTITUIR OS POSTES. | Y38: =VLOOKUP(pub?gid_1064752002_single_true_output_csv[[#This Row],[Column3]],UTDNOVEMBRO!B:P,15,FALSE) -> 30/10/25 | Z38: =VLOOKUP(pub?gid_1064752002_single_true_output_csv[[#This Row],[Column3]],UTDNOVEMBRO!B:Q,15,FALSE) -> 30/10/25
A39: REVERTON | B39: RENATO | C39: B-1227921 | D39: ER-CIND-PR -VARIANTE II-RURAL | E39: SÃO GABRIEL | F39: QLP | G39: ENERGIZADA | H39: 5 | I39: 03/11/2025 | J39: 03/11/2025 | K39: ENERGIZADA | O39: 5 | P39: 5 | Q39: =VLOOKUP(pub?gid_1064752002_single_true_output_csv[[#This Row],[Column3]],UTDNOVEMBRO!B:AQ,42,FALSE) -> -11,164902 | R39: =VLOOKUP(pub?gid_1064752002_single_true_output_csv[[#This Row],[Column3]],UTDNOVEMBRO!B:AU,43,FALSE) -> -41,781158 | S39: =VLOOKUP(pub?gid_1064752002_single_true_output_csv[[#This Row],[Column3]],UTDNOVEMBRO!B:AC,28,FALSE) -> 1 | T39: =VLOOKUP(pub?gid_1064752002_single_true_output_csv[[#This Row],[Column3]],UTDNOVEMBRO!B:C,2,FALSE) -> N/A | U39: =VLOOKUP(pub?gid_1064752002_single_true_output_csv[[#This Row],[Column3]],UTDNOVEMBRO!B:D,3,FALSE) -> N/A | V39: =VLOOKUP(pub?gid_1064752002_single_true_output_csv[[#This Row],[Column3]],UTDNOVEMBRO!B:K,10,FALSE) -> FLAVIO ALMEIDA DOS ANJOS - U468839 | W39: =VLOOKUP(pub?gid_1064752002_single_true_output_csv[[#This Row],[Column3]],UTDNOVEMBRO!B:N,13,FALSE) -> 21/10/25 | X39: =VLOOKUP(pub?gid_1064752002_single_true_output_csv[[#This Row],[Column3]],UTDNOVEMBRO!B:O,14,FALSE) -> ACESSAR A OBRA PELO PONTO ENVIADO NA VISITA. É SO IR RETO E DEPOIS ENTRAR A DIREITA NA N1-3. AI É SO SEGUIR A REDE. | Y39: =VLOOKUP(pub?gid_1064752002_single_true_output_csv[[#This Row],[Column3]],UTDNOVEMBRO!B:P,15,FALSE) -> 21/10/25 | Z39: =VLOOKUP(pub?gid_1064752002_single_true_output_csv[[#This Row],[Column3]],UTDNOVEMBRO!B:Q,15,FALSE) -> 21/10/25
A40: GIORLAN | B40: RENATO | C40: B-1228914 | D40: ER-CIND-POV-CANOAOZINHO-RURAL | E40: PRESIDENTE DUTRA | F40: QLP | G40: ENERGIZADA | H40: 6 | I40: 06/11/2025 | J40: 11/11/2025 | K40: ENERGIZADA | M40: DP | O40: 6 | P40: 6 | Q40: =VLOOKUP(pub?gid_1064752002_single_true_output_csv[[#This Row],[Column3]],UTDNOVEMBRO!B:AQ,42,FALSE) -> -11.306555 | R40: =VLOOKUP(pub?gid_1064752002_single_true_output_csv[[#This Row],[Column3]],UTDNOVEMBRO!B:AU,43,FALSE) -> -42.02167 | S40: =VLOOKUP(pub?gid_1064752002_single_true_output_csv[[#This Row],[Column3]],UTDNOVEMBRO!B:AC,28,FALSE) -> 1 | T40: =VLOOKUP(pub?gid_1064752002_single_true_output_csv[[#This Row],[Column3]],UTDNOVEMBRO!B:C,2,FALSE) -> N/A | U40: =VLOOKUP(pub?gid_1064752002_single_true_output_csv[[#This Row],[Column3]],UTDNOVEMBRO!B:D,3,FALSE) -> N/A | V40: =VLOOKUP(pub?gid_1064752002_single_true_output_csv[[#This Row],[Column3]],UTDNOVEMBRO!B:K,10,FALSE) -> JARBAS LIMA VIEIRA - U348612 | W40: =VLOOKUP(pub?gid_1064752002_single_true_output_csv[[#This Row],[Column3]],UTDNOVEMBRO!B:N,13,FALSE) -> 14/10/25 | X40: =VLOOKUP(pub?gid_1064752002_single_true_output_csv[[#This Row],[Column3]],UTDNOVEMBRO!B:O,14,FALSE) -> OBRA APITA PARA CONSTRUÇÃO CONFORME PROJETO | Y40: =VLOOKUP(pub?gid_1064752002_single_true_output_csv[[#This Row],[Column3]],UTDNOVEMBRO!B:P,15,FALSE) -> 20/10/25 | Z40: =VLOOKUP(pub?gid_1064752002_single_true_output_csv[[#This Row],[Column3]],UTDNOVEMBRO!B:Q,15,FALSE) -> 20/10/25
...

Sheet UTDNOVEMBRO
